<mujoco model="pendulum">

  <asset>
    <texture name="grid" type="2d" builtin="checker" rgb1=".1 .2 .3" rgb2=".2 .3 .4" width="300" height="300" mark="edge" markrgb=".2 .3 .4"/>
    <material name="grid" texture="grid" texrepeat="1 1" texuniform="true" reflectance=".2"/>
  </asset>

  <option timestep="0.002">
    <flag contact="disable" energy="enable"/>
  </option>

  <worldbody>
    <light name="light" pos="0 0 2"/>
    <geom name="floor" size="2 2 .2" type="plane" material="grid"/>
    <!-- <camera name="fixed" pos="0 -1.5 2" xyaxes='1 0 0 0 1 1'/> -->
    <!-- <camera name="lookat" mode="targetbodycom" target="pole" pos="0 -2 1"/> -->
    <body name="pole" pos="0 0 .6">
      <joint name="hinge" type="hinge" axis="0 1 0" damping="0.1"/>
      <geom name="base" type="cylinder" fromto="0 -.03 0 0 .03 0" size="0.021" mass="0.1"/>
      <geom name="pole" type="capsule" fromto="0 0 0 0 0 0.5" size="0.02" mass="0.1"/>
      <body name="mass" pos="0 0 0.5">
        <joint name="mass_joint" type="hinge" axis="0 0 1"/>
        <geom name="mass" type="sphere" pos="0 0 0" size="0.05" mass="0.1"/>
        <replicate count="8" euler="0 0 0.45">
          <site name="lidar_mass" pos="0 0 0.1" zaxis="1 0 0"/>
        </replicate>
      </body>
    </body>
  </worldbody>

  <actuator>
    <motor name="hinge_act_eff" joint="hinge" gear="1" ctrlrange="-1 1" ctrllimited="true"/>
  </actuator>

  <sensor>
    <jointpos name="hinge_position" joint="hinge" />
    <rangefinder site="lidar_mass"/>
  </sensor>
</mujoco>
